Workbook

Sheet Read-Me
B2: README: BATTERY FAILURE DATABANK - REVISION 2
B3: The Battery Failure Databank contains thermal runaway results gathered from nearly 300 small format fractional thermal runaway calorimetry (S-FTRC) experiments. A majority of these experiments were conducted at synchrotron facilities where high-speed x-ray videography was conducted of the cell while tested inside of the S-FTRC. The databank is a two-component system which consists of a Microsoft ExcelTM spreadsheet which provides S-FTRC results in tabular format and a radiographic video library containing the high-speed x-ray videos. When applicable, the Test ID is hyperlinked to the corresponding x-ray video. Overall, the databank provides results from S-FTRC experiments conducted on a mixture of commercially available lithium-ion (Li-ion) cells and specialized Li-ion test cells with varying cell format (18650, 21700, and D-cell) and trigger mechanism (heaters, heaters plus internal short circuiting device, and nail penetration). Please note that trade names and trademarks are used in this report for identification only. Their usage does not constitute an official endorsement, either expressed or implied, by the National Aeronautics and Space Administration.
B5: Relevant Acronyms and Abbreviations
B6: ISC | C6: Internal Short Circuit
B7: S-FTRC | C7: Small-Format Fractional Thermal Runaway Calorimeter
B10: Custom Cell Configurations
B11: Soteria 18650 (Control) | C11: 2.1 Ah Li-ion cell, constructed by Coulometrics, with standard separator and current collectors.
B12: Soteria 18650 (AL) | C12: 2.1 Ah Li-ion cell, constructed by Coulometrics, with a Soteria aluminum coated plastic current collector, a standard copper current collector, and a standard separator.
B13: Soteria 18650 (CU) | C13: 2.1 Ah Li-ion cell, constructed by Coulometrics, with a Soteria copper coated plastic current collector, a standard aluminum current collector, and a standard separator.
B14: Soteria 18650 (ALCU) | C14: 2.1 Ah Li-ion cell, constructed by Coulometrics, with both Soteria aluminum and copper coated plastic current collectors and a standard separator.
B15: Soteria 18650 (DW) | C15: 2.1 Ah Li-ion cell, constructed by Coulometrics, with standard current collectors and with a Dreamweaver Gold separator.
B16: Soteria 18650 (ALDW) | C16: 2.1 Ah Li-ion cell, constructed by Coulometrics, with a Soteria aluminum coated plastic current collector, a standard copper current collector, and with a Dreamweaver Gold separator.
B17: Soteria 18650 (ALCUDW) | C17: 2.1 Ah Li-ion cell, constructed by Coulometrics, with both Soteria aluminum and copper coated plastic current collectors and also with a Dreamweaver Gold separator.
B18: MOLiCEL 18650-Test Cell | C18: 2.37 Ah Li-ion cell, constructed by MOLiCEL, with an internal short circuiting (ISC) device built in.
B19: MOLiCEL 18650-Test Cell (DW-Gold) | C19: 2.37 Ah Li-ion cell, constructed by MOLiCEL, with a Dreamweaver Gold Separator and an internal short circuiting (ISC) device built in.
B20: MOLiCEL 18650-Test Cell (DW-Silver) | C20: 2.37 Ah Li-ion cell, constructed by MOLiCEL, with a Dreamweaver Silver Separator and an internal short circuiting (ISC) device built in.
B21: LG 18650-Test Cell (BV-250) | C21: 3.35 Ah Li-ion cell test cell, constructed by LG, with a bottom vent and a cell casing with a 250 µm thickness. Some cells also had an ISC device built in.
B22: LG 18650-Test Cell (BV-220) | C22: 3.35 Ah Li-ion cell test cell, constructed by LG, with a bottom vent and a cell casing with a 220 µm thickness. Some cells also had an ISC device built in.
... B70: Bottom-Vent-Yes-No | C70: Description of whether or not the cell design has a bottom vent or not.

Sheet Cell-Characteristics
B2: 1 | C2: =B2+1 -> 2 | D2: =C2+1 -> 3 | E2: =D2+1 -> 4 | F2: =E2+1 -> 5 | G2: =F2+1 -> 6 | H2: =G2+1 -> 7 | I2: =H2+1 -> 8 | J2: =I2+1 -> 9 | ... Q2: =P2+1 -> 16
B3: Cell-Description | C3: Cell-Format | D3: Cell-Capacity-Ah | E3: Cell-Nominal-Voltage-V | F3: Cell-Energy-Wh | G3: Specific-Energy-Wh/kg | H3: Energy-Density-Wh/L | I3: Cathode-Characteristics | J3: Anode-Characteristics | K3: Cell-Type | L3: Cell-Casing-Thickness-µm | M3: Bottom-Vent-Yes-No | N3: Surface-Area-Casing-Side-cm2 | O3: Surface-Area-Top-cm2 | P3: Surface-Area-Bottom-cm2 | Q3: Surface-Area-Total-cm2
B4: KULR 18650-K330 | C4: 18650 | D4: 3.3 | E4: 3.6 | F4: 11.88 | G4: =F4/(47/1000) -> 252.76596 | H4: 718 | I4: - | J4: - | K4: - | L4: 220 | M4: Yes | N4: =(3.14*1.84)*6.54 -> 37.785504 | O4: =3.14*((1.84/2)^2) -> 2.657696 | P4: =O4 -> 2.657696 | Q4: =SUM(N4:P4) -> 43.100896
B5: KULR 21700-K500 | C5: 21700 | D5: 5 | E5: 3.6 | F5: 18 | G5: =F5/(70/1000) -> 257.14286 | H5: 740 | I5: - | J5: - | K5: - | L5: 220 | M5: Yes | N5: =(3.14*2.17)*7.9 -> 53.82902 | O5: =3.14*((2.17/2)^2) -> 3.6964865 | P5: =O5 -> 3.6964865 | Q5: =SUM(N5:P5) -> 61.221993
B6: LG 18650-HG2 | C6: 18650 | D6: 3 | E6: 3.6 | F6: 10.8 | G6: =F6/(47/1000) -> 229.78723 | I6: - | J6: - | K6: - | L6: 150 | M6: No | N6: =(3.14*1.83)*6.5 -> 37.3503 | O6: =3.14*((1.83/2)^2) -> 2.6288865 | P6: =O6 -> 2.6288865 | Q6: =SUM(N6:P6) -> 42.608073
B7: LG 18650-M36 | C7: 18650 | D7: 3.44 | E7: 3.63 | F7: 12.4872 | G7: =F7/(48.2/1000) -> 259.07054 | I7: - | J7: - | K7: - | L7: 250 | M7: No | N7: =(3.14*1.8)*6.5 -> 36.738 | O7: =3.14*(0.9^2) -> 2.5434 | P7: =O7 -> 2.5434 | Q7: =SUM(N7:P7) -> 41.8248
B8: LG 18650-Test Cell (NBV-250) | C8: 18650 | D8: 3.44 | E8: 3.63 | F8: 12.4872 | I8: - | J8: - | K8: - | L8: 250 | M8: No | N8: =(3.14*1.8)*6.5 -> 36.738 | O8: =3.14*(0.9^2) -> 2.5434 | P8: =O8 -> 2.5434 | Q8: =SUM(N8:P8) -> 41.8248
B9: LG 18650-Test Cell (NBV-220) | C9: 18650 | D9: 3.44 | E9: 3.63 | F9: 12.4872 | I9: - | J9: - | K9: - | L9: 220 | M9: No | N9: =(3.14*1.8)*6.5 -> 36.738 | O9: =3.14*(0.9^2) -> 2.5434 | P9: =O9 -> 2.5434 | Q9: =SUM(N9:P9) -> 41.8248
B10: LG 18650-Test Cell (BV-250) | C10: 18650 | D10: 3.44 | E10: 3.63 | F10: 12.4872 | I10: - | J10: - | K10: - | L10: 250 | M10: Yes | N10: =(3.14*1.8)*6.5 -> 36.738 | O10: =3.14*(0.9^2) -> 2.5434 | P10: =O10 -> 2.5434 | Q10: =SUM(N10:P10) -> 41.8248
B11: LG 18650-Test Cell (BV-220) | C11: 18650 | D11: 3.44 | E11: 3.63 | F11: 12.4872 | I11: - | J11: - | K11: - | L11: 220 | M11: Yes | N11: =(3.14*1.8)*6.5 -> 36.738 | O11: =3.14*(0.9^2) -> 2.5434 | P11: =O11 -> 2.5434 | Q11: =SUM(N11:P11) -> 41.8248
B12: LG 18650-MJ1 (Korean) | C12: 18650 | D12: 3.5 | E12: 3.6285714 | F12: 12.7 | G12: 261 | H12: 738 | I12: LiNiMnCoO2 | J12: Carbon | K12: - | L12: - | M12: No | N12: =(3.14*1.8)*6.5 -> 36.738 | O12: =3.14*(0.9^2) -> 2.5434 | P12: =O12 -> 2.5434 | Q12: =SUM(N12:P12) -> 41.8248
B13: LG 18650-MJ1 (Chinese) | C13: 18650 | D13: 3.5 | E13: 3.6285714 | F13: 12.7 | G13: 261 | H13: 738 | I13: LiNiMnCoO2 | J13: Carbon | K13: - | L13: - | M13: No | N13: =(3.14*1.8)*6.5 -> 36.738 | O13: =3.14*(0.9^2) -> 2.5434 | P13: =O13 -> 2.5434 | Q13: =SUM(N13:P13) -> 41.8248
B14: LG 21700-M50 (BV) | C14: 21700 | D14: 5.0137741 | E14: 3.63 | F14: 18.2 | I14: - | J14: - | K14: - | L14: - | M14: Yes | N14: =(3.14*2.11)*7.15 -> 47.37161 | O14: =3.14*((2.11/2)^2) -> 3.4948985 | P14: =O14 -> 3.4948985 | Q14: =SUM(N14:P14) -> 54.361407
B15: MOLiCEL 18650-J | C15: 18650 | D15: 2.37 | E15: 3.7 | F15: 8.769 | I15: - | J15: - | K15: - | L15: - | M15: No | N15: =(3.14*1.8)*6.5 -> 36.738 | O15: =3.14*(0.9^2) -> 2.5434 | P15: =O15 -> 2.5434 | Q15: =SUM(N15:P15) -> 41.8248
B16: MOLiCEL 18650-Test Cell | C16: 18650 | D16: 2.37 | E16: 3.7 | F16: 8.769 | I16: - | J16: - | K16: - | L16: - | M16: No | N16: =(3.14*1.8)*6.5 -> 36.738 | O16: =3.14*(0.9^2) -> 2.5434 | P16: =O16 -> 2.5434 | Q16: =SUM(N16:P16) -> 41.8248
B17: MOLiCEL 18650-Test Cell (DW-Gold) | C17: 18650 | D17: 2.37 | E17: 3.7 | F17: 8.769 | I17: - | J17: - | K17: - | L17: - | M17: No | N17: =(3.14*1.8)*6.5 -> 36.738 | O17: =3.14*(0.9^2) -> 2.5434 | P17: =O17 -> 2.5434 | Q17: =SUM(N17:P17) -> 41.8248
B18: MOLiCEL 18650-Test Cell (DW-Silver) | C18: 18650 | D18: 2.37 | E18: 3.7 | F18: 8.769 | I18: - | J18: - | K18: - | L18: - | M18: No | N18: =(3.14*1.8)*6.5 -> 36.738 | O18: =3.14*(0.9^2) -> 2.5434 | P18: =O18 -> 2.5434 | Q18: =SUM(N18:P18) -> 41.8248
B19: MOLiCEL 18650-M35A | C19: 18650 | D19: 3.5 | E19: 3.6 | F19: 12.6 | I19: - | J19: - | K19: - | L19: - | M19: No | N19: =(3.14*1.8)*6.5 -> 36.738 | O19: =3.14*(0.9^2) -> 2.5434 | P19: =O19 -> 2.5434 | Q19: =SUM(N19:P19) -> 41.8248
B20: MOLiCEL 18650-P28A | C20: 18650 | D20: 2.8 | E20: 3.6 | F20: 10.08 | I20: - | J20: - | K20: - | L20: - | M20: No | N20: =(3.14*3.3)*6 -> 62.172 | O20: =3.14*(1.65^2) -> 8.54865 | P20: =O20 -> 8.54865 | Q20: =SUM(N20:P20) -> 79.2693
B21: Panasonic 18650-BE | C21: 18650 | D21: 3.2 | E21: 3.6 | F21: =E21*D21 -> 11.52 | G21: 238 | H21: 681 | I21: LiNiCoAl | J21: Carbon | K21: Energy | L21: - | M21: Yes | N21: =(3.14*1.82)*6.51 -> 37.203348 | O21: =3.14*(0.91^2) -> 2.600234 | P21: =O21 -> 2.600234 | Q21: =SUM(N21:P21) -> 42.403816 | S21: Panasonic BE 18650 Battery, 3200mAh, 3.63A, 3.6V, Grade A Lithium-ion (NCR18650BE) - 18650 Battery - Lithium Ion Battery - Voltaplex
B22: Saft D-Cell-VES16 | C22: D-Cell | D22: 4.5 | E22: 3.6 | F22: 16.2 | G22: 140 | H22: 314 | I22: NCA | J22: Carbon | K22: - | L22: 380 | M22: No | N22: =(3.14*1.8)*6.5 -> 36.738 | O22: =3.14*(0.9^2) -> 2.5434 | P22: =O22 -> 2.5434 | Q22: =SUM(N22:P22) -> 41.8248 | S22: Microsoft PowerPoint - Y Borthomieu VES16 cells and Batteries.ppt [Mode de compatibilité] (nasa.gov)
B23: Samsung 18650-26J | C23: 18650 | D23: 2.6 | E23: 3.63 | F23: 9.438 | I23: - | J23: - | K23: - | L23: - | M23: No | N23: =(3.14*1.8)*6.5 -> 36.738 | O23: =3.14*(0.9^2) -> 2.5434 | P23: =O23 -> 2.5434 | Q23: =SUM(N23:P23) -> 41.8248
B24: Samsung 18650-30Q | C24: 18650 | D24: 3 | E24: 3.6 | F24: 10.8 | I24: - | J24: - | K24: - | L24: - | M24: No | N24: =(3.14*1.8)*6.5 -> 36.738 | O24: =3.14*(0.9^2) -> 2.5434 | P24: =O24 -> 2.5434 | Q24: =SUM(N24:P24) -> 41.8248
B25: Sanyo 18650-A | C25: 18650 | D25: 2.15 | E25: 3.6 | F25: 7.74 | I25: - | J25: - | K25: - | M25: No | N25: =(3.14*1.8)*6.5 -> 36.738 | O25: =3.14*(0.9^2) -> 2.5434 | P25: =O25 -> 2.5434 | Q25: =SUM(N25:P25) -> 41.8248
B26: Sony 18650-VTC6 | C26: 18650 | D26: 3.13 | E26: 3.6 | F26: 11.268 | G26: 237 | H26: 617 | I26: LiNiMnCoO2 or NCA? UCL did not detect Manganese | J26: Carbon | K26: - | L26: - | M26: No | N26: =(3.14*1.8)*6.5 -> 36.738 | O26: =3.14*(0.9^2) -> 2.5434 | P26: =O26 -> 2.5434 | Q26: =SUM(N26:P26) -> 41.8248
B27: Sony 18650-VC7 | C27: 18650 | D27: 3.53 | E27: 3.5977337 | F27: 12.7 | G27: 267 | H27: 719 | I27: - | J27: - | K27: - | L27: - | M27: Yes | N27: =(3.14*1.8)*6.5 -> 36.738 | O27: =3.14*(0.9^2) -> 2.5434 | P27: =O27 -> 2.5434 | Q27: =SUM(N27:P27) -> 41.8248
B28: Soteria 18650 (Control) | C28: 18650 | D28: 2.1 | E28: 3.65 | F28: 7.665 | I28: - | J28: - | K28: - | L28: 250 | M28: No | N28: =(3.14*1.8)*6.5 -> 36.738 | O28: =3.14*(0.9^2) -> 2.5434 | P28: =O28 -> 2.5434 | Q28: =SUM(N28:P28) -> 41.8248
B29: Soteria 18650 (AL) | C29: 18650 | D29: 2.1 | E29: 3.65 | F29: 7.665 | I29: - | J29: - | K29: - | L29: 250 | M29: No | N29: =(3.14*1.8)*6.5 -> 36.738 | O29: =3.14*(0.9^2) -> 2.5434 | P29: =O29 -> 2.5434 | Q29: =SUM(N29:P29) -> 41.8248
B30: Soteria 18650 (CU) | C30: 18650 | D30: 2.1 | E30: 3.65 | F30: 7.665 | I30: - | J30: - | K30: - | L30: 250 | M30: No | N30: =(3.14*1.8)*6.5 -> 36.738 | O30: =3.14*(0.9^2) -> 2.5434 | P30: =O30 -> 2.5434 | Q30: =SUM(N30:P30) -> 41.8248
B31: Soteria 18650 (ALCU) | C31: 18650 | D31: 2.1 | E31: 3.65 | F31: 7.665 | I31: - | J31: - | K31: - | L31: 250 | M31: No | N31: =(3.14*1.8)*6.5 -> 36.738 | O31: =3.14*(0.9^2) -> 2.5434 | P31: =O31 -> 2.5434 | Q31: =SUM(N31:P31) -> 41.8248
B32: Soteria 18650 (DW) | C32: 18650 | D32: 2.1 | E32: 3.65 | F32: 7.665 | I32: - | J32: - | K32: - | L32: 250 | M32: No | N32: =(3.14*1.8)*6.5 -> 36.738 | O32: =3.14*(0.9^2) -> 2.5434 | P32: =O32 -> 2.5434 | Q32: =SUM(N32:P32) -> 41.8248
B33: Soteria 18650 (ALDW) | C33: 18650 | D33: 2.1 | E33: 3.65 | F33: 7.665 | I33: - | J33: - | K33: - | L33: 250 | M33: No | N33: =(3.14*1.8)*6.5 -> 36.738 | O33: =3.14*(0.9^2) -> 2.5434 | P33: =O33 -> 2.5434 | Q33: =SUM(N33:P33) -> 41.8248
B34: Soteria 18650 (ALCUDW) | C34: 18650 | D34: 2.1 | E34: 3.65 | F34: 7.665 | I34: - | J34: - | K34: - | L34: 250 | M34: No | N34: =(3.14*1.8)*6.5 -> 36.738 | O34: =3.14*(0.9^2) -> 2.5434 | P34: =O34 -> 2.5434 | Q34: =SUM(N34:P34) -> 41.8248
K36: -

Sheet Fractional-Calorimetry-Data
B3: Cell-Description | C3: Test-ID | D3: Test-Series | E3: Trigger-Mechanism | F3: S-FTRC-Generation | G3: Data-Processing-Utility | H3: Test-Date | I3: Cell-ID-Number | J3: Pre-Test-State-of-Charge-% | K3: Pre-Test-Cell-Open-Circuit-Voltage-V | L3: Pre-Test-Cell-Mass-g | M3: Pre-Test-Positive-Copper-Mesh-Mass-g | N3: Pre-Test-Negative-Copper-Mesh-Mass-g | O3: Pressure-Assisted-Seal-Configuration-Positive | P3: Pressure-Assisted-Seal-Configuration-Negative | Q3: Cell-Failure-Mechanism | R3: Baseline-Total-Energy-Yield-kJ | S3: Conductive-Heat-Loss-Rate-kJs-1 | T3: Baseline-Plus-Heat-Loss-Total-Energy-Yield-kJ | U3: Corrected-Total-Energy-Yield-kJ | V3: Energy-Fraction-Cell-Body-kJ | W3: Energy-Fraction-Positive-Ejecta-kJ | X3: Energy-Fraction-Negative-Ejecta-kJ | Y3: Energy-Percent-Cell-Body-% | Z3: Energy-Percent-Positive-Ejecta-% | AA3: Energy-Percent-Negative-Ejecta-% | AB3: Theoretical-Energy-Positive-Unrecovered-Mass-kJ | AC3: Theoretical-Energy-Negative-Unrecovered-Mass-kJ | AD3: Ƭ-Cell-Body | AE3: Ƭ-Positive | AF3: Ƭ-Negative | AG3: Heater-Power-W | AH3: Heater-Time-On-s | AI3: Energy-Applied-to-Trigger-kJ | AJ3: Onset-Selection-Time-s | AK3: Avg-Cell-Temp-At-Trigger-degC | AL3: Post-Test-Mass-Cell-Body-g | AM3: Post-Test-Mass-Positive-Ejecta-Mating-g | AN3: Post-Test-Mass-Positive-Ejecta-Bore-Baffles-g | AO3: Post-Test-Mass-Positive-Copper-Mesh-g | AP3: Post-Test-Mass-Negative-Ejecta-Mating-g | AQ3: Post-Test-Mass-Negative-Ejecta-Bore-Baffles-g | AR3: Post-Test-Mass-Negative-Copper-Mesh-g | AS3: Post-Test-Mass-Unrecovered-g | AT3: Mass-Ejected | AU3: Percent-Original-Mass-Ejected | AV3: Post-Test-Open-Circuit-Voltage-V | AW3: Test-Notes | AX3: Radiography-Notes | AY3: Radiography-File-Names | AZ3: Radiography-ROI | BA3: Radiographic-Video-Availability | BB3: EYA-Processing-Notes | BC3: TC-Failure-Count | BD3: TC-Failure-Percent-% | BE3: Total-Energy-Ratio | BF3: Heat-Rate-Cell-Body-W | BG3: Heat-Rate-Positive-W | BH3: Heat-Rate-Negative-W | BI3: Heat-Rate-Entire-Cell-W | BJ3: Heat-Flux-Cell-Body-W/cm2 | BK3: Heat-Flux-Positive-W/cm2 | BL3: Heat-Flux-Negative-W/cm2 | BM3: Heat-Flux-Entire-Cell-W/cm2 | BN3: Average-Event-Length-s
B4: KULR 18650-K330 | C4: DLS19_Dec_Run036 | D4: DLS19_Dec | E4: Heater (ISC) | F4: V10.0 | G4: EYAN_1.1_B | H4: 43812 | I4: 66 | J4: 100 | K4: 4.2 | L4: 47.3927 | M4: 52.8 | N4: 53.4 | O4: 18650-Aluminum | P4: 18650-Brass | Q4: Top and Bottom Vent | R4: 52.184734 | S4: 0.034 | T4: 55.106215 | U4: 55.679663 | V4: 22.050797 | W4: 20.154016 | X4: 13.474849 | Y4: 39.602964 | Z4: 36.196369 | AA4: 24.200666 | AB4: 0.31466058 | AC4: 0.25878739 | AD4: 5.5099 | AE4: 3.9047 | AF4: 4.1064 | AG4: 939.9274 | AH4: 61.0576 | AI4: 57.229817 | AJ4: 73.0673 | AK4: 130.16562 | AL4: 24.2 | AM4: 2.4 | AN4: 7.3 | AO4: 1.3 | AP4: 0.3 | AQ4: 3.3 | AR4: 0.5 | AS4: 8.0927 | AT4: 23.1927 | AU4: 48.937284 | AV4: 0 | AW4: TCs 57, 95 are not working properly. TR ensued fairly quickly. Gamry failure, overcharged | AX4: 95872 (data), 95873 (bright), 95871 (dark) | AY4: None Recorded | AZ4: Top | BA4: Available | BB4: - | BC4: 6 | BD4: 7.4074074 | BE4: =U4/((VLOOKUP(B4,'Cell-Characteristics'!$B$4:$E$34,3,FALSE)*VLOOKUP(B4,'Cell-Characteristics'!$B$4:$E$34,4,FALSE)*3600)/1000) -> 1.3019001 | BF4: =(1000*V4)/AD4 -> 4002.0321 | BG4: =(1000*W4)/AE4 -> 5161.4763 | BH4: =(1000*X4)/AF4 -> 3281.4264 | BI4: =(1000*U4)/AVERAGE(AD4:AF4) -> 12354.041 | BJ4: =BF4/((VLOOKUP(B4,'Cell-Characteristics'!$B$4:$Q$34,13,FALSE))) -> 105.91448 | BK4: =BG4/((VLOOKUP(B4,'Cell-Characteristics'!$B$4:$Q$34,14,FALSE))) -> 1942.0868 | BL4: =BH4/((VLOOKUP(B4,'Cell-Characteristics'!$B$4:$Q$34,15,FALSE))) -> 1234.6884 | BM4: =BI4/((VLOOKUP(B4,'Cell-Characteristics'!$B$4:$Q$34,16,FALSE))) -> 286.63072 | BN4: =AVERAGE(AD4:AF4) -> 4.507
B5: KULR 18650-K330 | C5: DLS19_Dec_Run037 | D5: DLS19_Dec | E5: Heater (ISC) | F5: V10.0 | G5: EYAN_1.1_B | H5: 43812 | I5: 64 | J5: 100 | K5: 4.122 | L5: 47.2264 | M5: 50.4 | N5: 52 | O5: 18650-Aluminum | P5: 18650-Brass | Q5: Top and Bottom Vent | R5: 57.13917 | S5: 0.0377 | T5: 59.00122 | U5: 60.970046 | V5: 13.813677 | W5: 9.3900572 | X5: 37.766312 | Y5: 22.656497 | Z5: 15.401099 | AA5: 61.942404 | AB5: 0.62717994 | AC5: 1.3416465 | AD5: 5.2184 | AE5: 1.8057 | AF5: 1.7041 | AG5: 932.14467 | AH5: 71.4974 | AI5: 66.506964 | AJ5: 80.2176 | AK5: 165.03871 | AL5: 16.3 | AM5: 0.5 | AN5: 2.2 | AO5: 0 | AP5: 3.8 | AQ5: 8.4 | AR5: 0.5 | AS5: 15.5264 | AT5: 30.9264 | AU5: 65.485406 | AV5: 0 | AW5: TCs 30, 104 are reading but shouldn't be (check TC map). TCs 61, 63, 66 are not reading (open channels). | AX5: 95874 (data), 95875 (bright), 95871 (dark) | AY5: None Recorded | AZ5: Top | BA5: Available | BB5: - | BC5: 5 | BD5: 6.1728395 | BE5: =U5/((VLOOKUP(B5,'Cell-Characteristics'!$B$4:$E$34,3,FALSE)*VLOOKUP(B5,'Cell-Characteristics'!$B$4:$E$34,4,FALSE)*3600)/1000) -> 1.4255997 | BF5: =(1000*V5)/AD5 -> 2647.1096 | BG5: =(1000*W5)/AE5 -> 5200.2311 | BH5: =(1000*X5)/AF5 -> 22162.028 | BI5: =(1000*U5)/AVERAGE(AD5:AF5) -> 20956.227 | BJ5: =BF5/((VLOOKUP(B5,'Cell-Characteristics'!$B$4:$Q$34,13,FALSE))) -> 70.05622 | BK5: =BG5/((VLOOKUP(B5,'Cell-Characteristics'!$B$4:$Q$34,14,FALSE))) -> 1956.6689 | BL5: =BH5/((VLOOKUP(B5,'Cell-Characteristics'!$B$4:$Q$34,15,FALSE))) -> 8338.8123 | BM5: =BI5/((VLOOKUP(B5,'Cell-Characteristics'!$B$4:$Q$34,16,FALSE))) -> 486.21325 | BN5: =AVERAGE(AD5:AF5) -> 2.9094
B6: KULR 18650-K330 | C6: DLS19_Dec_Run038 | D6: DLS19_Dec | E6: Heater (ISC) | F6: V10.0 | G6: EYAN_1.1_B | H6: 43812 | I6: 58 | J6: 100 | K6: 4.254 | L6: 47.3518 | M6: 50.1 | N6: 48.3 | O6: 18650-Brass | P6: 18650-Brass | Q6: Top Vent Only - Bottom Vent Not Actuated | R6: 56.977466 | S6: 0.0427 | T6: 59.14736 | U6: 62.879185 | V6: 6.0733609 | W6: 55.841541 | X6: 0.96428321 | Y6: 9.6587781 | Z6: 88.807673 | AA6: 1.5335492 | AB6: 3.7318252 | AC6: 0 | AD6: 8.2189 | AE6: 1.5002 | AF6: 0 | AG6: 950.47324 | AH6: 84.8873 | AI6: 80.460989 | AJ6: 91.9055 | AK6: 219.34555 | AL6: 12.3 | AM6: 4.2 | AN6: 7.7 | AO6: 2.2 | AP6: 0.3 | AQ6: 0.1 | AR6: 0 | AS6: 20.5518 | AT6: 35.0518 | AU6: 74.024219 | AV6: 0 | AW6: TC 93 not working. TR runaway ensued shortly therefter. `dpa revealed that cell may have been installed upside down - i.e. bottom vent facing positive side of calorimeter. `donal and will need to pay attention to this in respective analysis. the masses of positive side soot are probably for the bv side and the negative side soot masses are probably for the button side masses.\ Gamry failure, overcharged | AX6: 95876 (data), 95877 (bright), 95871 (dark) | AY6: None Recorded | AZ6: Middle | BA6: Available | BB6: - | BC6: 5 | BD6: 6.1728395 | BE6: =U6/((VLOOKUP(B6,'Cell-Characteristics'!$B$4:$E$34,3,FALSE)*VLOOKUP(B6,'Cell-Characteristics'!$B$4:$E$34,4,FALSE)*3600)/1000) -> 1.4702391 | BF6: =(1000*V6)/AD6 -> 738.95058 | BG6: =(1000*W6)/AE6 -> 37222.731 | BH6: =(1000*X6)/AF6 -> #DIV/0! | BI6: =(1000*U6)/AVERAGE(AD6:AF6) -> 19408.953 | BJ6: =BF6/((VLOOKUP(B6,'Cell-Characteristics'!$B$4:$Q$34,13,FALSE))) -> 19.556457 | BK6: =BG6/((VLOOKUP(B6,'Cell-Characteristics'!$B$4:$Q$34,14,FALSE))) -> 14005.639 | BL6: =BH6/((VLOOKUP(B6,'Cell-Characteristics'!$B$4:$Q$34,15,FALSE))) -> #DIV/0! | BM6: =BI6/((VLOOKUP(B6,'Cell-Characteristics'!$B$4:$Q$34,16,FALSE))) -> 450.31437 | BN6: =AVERAGE(AD6:AF6) -> 3.2397
B7: KULR 18650-K330 | C7: DLS19_Dec_Run039 | D7: DLS19_Dec | E7: Heater (ISC) | F7: V10.0 | G7: EYAN_1.1_B | H7: 43812 | I7: 52 | J7: 100 | K7: 4.119 | L7: 47.369 | M7: 47.7 | N7: 49.7 | O7: 18650-Brass | P7: 18650-Brass | Q7: Top and Bottom Vent | R7: 53.058256 | S7: 0.0354 | T7: 55.186553 | U7: 56.111607 | V7: 19.087168 | W7: 7.5009621 | X7: 29.523478 | Y7: 34.016434 | Z7: 13.367933 | AA7: 52.615633 | AB7: 0.24058064 | AC7: 0.68447331 | AD7: 7.2209 | AE7: 3.8093 | AF7: 1.6043 | AG7: 944.00255 | AH7: 67.9722 | AI7: 63.89096 | AJ7: 78.4824 | AK7: 139.85181 | AL7: 23.3 | AM7: 0.2 | AN7: 3.2 | AO7: 0.3 | AP7: 1.3 | AQ7: 6.8 | AR7: 1.9 | AS7: 10.369 | AT7: 24.069 | AU7: 50.811712 | AV7: 0 | AW7: TCs 57, 95 not working properly. TR event was pretty nominal. | AX7: 95878 (data), 95879 (bright), 95871 (dark) | AY7: None Recorded | AZ7: Middle | BA7: Available | BB7: - | BC7: 5 | BD7: 6.1728395 | BE7: =U7/((VLOOKUP(B7,'Cell-Characteristics'!$B$4:$E$34,3,FALSE)*VLOOKUP(B7,'Cell-Characteristics'!$B$4:$E$34,4,FALSE)*3600)/1000) -> 1.3119998 | BF7: =(1000*V7)/AD7 -> 2643.3225 | BG7: =(1000*W7)/AE7 -> 1969.1182 | BH7: =(1000*X7)/AF7 -> 18402.716 | BI7: =(1000*U7)/AVERAGE(AD7:AF7) -> 13323.426 | BJ7: =BF7/((VLOOKUP(B7,'Cell-Characteristics'!$B$4:$Q$34,13,FALSE))) -> 69.955995 | BK7: =BG7/((VLOOKUP(B7,'Cell-Characteristics'!$B$4:$Q$34,14,FALSE))) -> 740.91177 | BL7: =BH7/((VLOOKUP(B7,'Cell-Characteristics'!$B$4:$Q$34,15,FALSE))) -> 6924.312 | BM7: =BI7/((VLOOKUP(B7,'Cell-Characteristics'!$B$4:$Q$34,16,FALSE))) -> 309.12178 | BN7: =AVERAGE(AD7:AF7) -> 4.2115
B8: KULR 18650-K330 | C8: DLS19_Dec_Run041 | D8: DLS19_Dec | E8: Heater (ISC) | F8: V10.0 | G8: EYAN_1.1_B | H8: 43812 | I8: 62 | J8: 100 | K8: 4.144 | L8: 47.4738 | M8: 47.5 | N8: 49.9 | O8: 18650-Brass | P8: 18650-Brass | Q8: Top and Bottom Vent | R8: 59.781345 | S8: 0.0483 | T8: 61.939964 | U8: 63.683843 | V8: 9.6154865 | W8: 6.3849879 | X8: 47.683369 | Y8: 15.098785 | Z8: 10.026072 | AA8: 74.875143 | AB8: 0.33689128 | AC8: 1.4069876 | AD8: 7.0316 | AE8: 2.6117 | AF8: 1.9051 | AG8: 948.70397 | AH8: 108.7464 | AI8: 102.91701 | AJ8: 122.9653 | AK8: 239.83976 | AL8: 15.1 | AM8: 0.1 | AN8: 1.2 | AO8: 0 | AP8: 5.5 | AQ8: 12.1 | AR8: 1.1 | AS8: 12.3738 | AT8: 32.3738 | AU8: 68.192982 | AV8: 0 | AW8: TC 95 not working. DPA- Jelly roll ejeted via negtive terminus residing inside the mating | AX8: 95905 (data), 95904 (brights), 95899 (dark) | AY8: None Recorded | AZ8: Middle | BA8: Available | BB8: - | BC8: 4 | BD8: 4.9382716 | BE8: =U8/((VLOOKUP(B8,'Cell-Characteristics'!$B$4:$E$34,3,FALSE)*VLOOKUP(B8,'Cell-Characteristics'!$B$4:$E$34,4,FALSE)*3600)/1000) -> 1.4890536 | BF8: =(1000*V8)/AD8 -> 1367.4678 | BG8: =(1000*W8)/AE8 -> 2444.7631 | BH8: =(1000*X8)/AF8 -> 25029.326 | BI8: =(1000*U8)/AVERAGE(AD8:AF8) -> 16543.55 | BJ8: =BF8/((VLOOKUP(B8,'Cell-Characteristics'!$B$4:$Q$34,13,FALSE))) -> 36.190275 | BK8: =BG8/((VLOOKUP(B8,'Cell-Characteristics'!$B$4:$Q$34,14,FALSE))) -> 919.88066 | BL8: =BH8/((VLOOKUP(B8,'Cell-Characteristics'!$B$4:$Q$34,15,FALSE))) -> 9417.6783 | BM8: =BI8/((VLOOKUP(B8,'Cell-Characteristics'!$B$4:$Q$34,16,FALSE))) -> 383.83308 | BN8: =AVERAGE(AD8:AF8) -> 3.8494667
B9: KULR 18650-K330 | C9: DLS19_Dec_Run085 | D9: DLS19_Dec | E9: Heater (ISC) | F9: V10.0 | G9: EYAN_1.1_B | H9: 43813 | I9: 50 | J9: 100 | K9: 4.148 | L9: 48.0584 | M9: 51.1 | N9: 52.1 | O9: 18650-Aluminum | P9: 18650-Brass | Q9: Top Vent Only - Bottom Vent Not Actuated | R9: 56.979652 | S9: 0.0443 | T9: 58.992585 | U9: 61.31424 | V9: 13.09342 | W9: 47.535478 | X9: 0.68534195 | Y9: 21.354615 | Z9: 77.527631 | AA9: 1.1177533 | AB9: 2.3216552 | AC9: 0 | AD9: 3.4088 | AE9: 1.9048 | AF9: 0 | AG9: 951.35559 | AH9: 102.2557 | AI9: 97.059224 | AJ9: 107.3737 | AK9: 231.28564 | AL9: 9.7 | AM9: 12.8 | AN9: 10.2 | AO9: 0.9 | AP9: 0 | AQ9: 0 | AR9: 0 | AS9: 14.4584 | AT9: 38.3584 | AU9: 79.816224 | AV9: 0 | AW9: TCs 93 is open. | AX9: 95987 (darks), 95990 (data), 95991 (brights) | AY9: None Recorded | AZ9: Top | BA9: Available | BB9: - | BC9: 5 | BD9: 6.1728395 | BE9: =U9/((VLOOKUP(B9,'Cell-Characteristics'!$B$4:$E$34,3,FALSE)*VLOOKUP(B9,'Cell-Characteristics'!$B$4:$E$34,4,FALSE)*3600)/1000) -> 1.4336476 | BF9: =(1000*V9)/AD9 -> 3841.0643 | BG9: =(1000*W9)/AE9 -> 24955.627 | BH9: =(1000*X9)/AF9 -> #DIV/0! | BI9: =(1000*U9)/AVERAGE(AD9:AF9) -> 34617.344 | BJ9: =BF9/((VLOOKUP(B9,'Cell-Characteristics'!$B$4:$Q$34,13,FALSE))) -> 101.65444 | BK9: =BG9/((VLOOKUP(B9,'Cell-Characteristics'!$B$4:$Q$34,14,FALSE))) -> 9389.9478 | BL9: =BH9/((VLOOKUP(B9,'Cell-Characteristics'!$B$4:$Q$34,15,FALSE))) -> #DIV/0! | BM9: =BI9/((VLOOKUP(B9,'Cell-Characteristics'!$B$4:$Q$34,16,FALSE))) -> 803.16994 | BN9: =AVERAGE(AD9:AF9) -> 1.7712
B10: KULR 18650-K330 | C10: DLS19_Dec_Run086 | D10: DLS19_Dec | E10: Heater (ISC) | F10: V10.0 | G10: EYAN_1.1_B | H10: 43813 | I10: 53 | J10: 100 | K10: 4.129 | L10: 47.394 | M10: 45.2 | N10: 48.7 | O10: 18650-Brass | P10: 18650-Brass | Q10: Top and Bottom Vent | R10: 50.119101 | S10: 0.043 | T10: 53.047248 | U10: 54.598821 | V10: 8.9088537 | W10: 3.775279 | X10: 41.914688 | Y10: 16.316934 | Z10: 6.9145798 | AA10: 76.768486 | AB10: 0.282615 | AC10: 1.2689576 | AD10: 1.5034 | AE10: 1.5034 | AF10: 1.4037 | AG10: 950.33651 | AH10: 104.4472 | AI10: 99.055564 | AJ10: 107.4492 | AK10: 223.21516 | AL10: 20 | AM10: 0 | AN10: 0 | AO10: 0 | AP10: 2.6 | AQ10: 7.7 | AR10: 4.8 | AS10: 12.294 | AT10: 27.394 | AU10: 57.800565 | AV10: 0 | AW10: TC 57, 87, 95 out | AX10: None Recorded | AY10: None Recorded | AZ10: Middle | BA10: None Recorded | BB10: - | BC10: 5 | BD10: 6.1728395 | BE10: =U10/((VLOOKUP(B10,'Cell-Characteristics'!$B$4:$E$34,3,FALSE)*VLOOKUP(B10,'Cell-Characteristics'!$B$4:$E$34,4,FALSE)*3600)/1000) -> 1.2766279 | BF10: =(1000*V10)/AD10 -> 5925.804 | BG10: =(1000*W10)/AE10 -> 2511.1607 | BH10: =(1000*X10)/AF10 -> 29860.147 | BI10: =(1000*U10)/AVERAGE(AD10:AF10) -> 37137.844 | BJ10: =BF10/((VLOOKUP(B10,'Cell-Characteristics'!$B$4:$Q$34,13,FALSE))) -> 156.82744 | BK10: =BG10/((VLOOKUP(B10,'Cell-Characteristics'!$B$4:$Q$34,14,FALSE))) -> 944.86379 | BL10: =BH10/((VLOOKUP(B10,'Cell-Characteristics'!$B$4:$Q$34,15,FALSE))) -> 11235.351 | BM10: =BI10/((VLOOKUP(B10,'Cell-Characteristics'!$B$4:$Q$34,16,FALSE))) -> 861.64901 | BN10: =AVERAGE(AD10:AF10) -> 1.4701667
B11: KULR 18650-K330 | C11: DLS19_Dec_Run087 | D11: DLS19_Dec | E11: Heater (ISC) | F11: V10.0 | G11: EYAN_1.1_B | H11: 43813 | I11: 54 | J11: 100 | K11: 4.124 | L11: 47.4415 | M11: 47.1 | N11: 48.1 | O11: 18650-Brass | P11: 18650-Brass | Q11: Top and Bottom Vent | R11: 58.511261 | S11: 0.0497 | T11: 61.10354 | U11: 62.788194 | V11: 8.4711806 | W11: 5.0416689 | X11: 49.275345 | Y11: 13.491677 | Z11: 8.0296447 | AA11: 78.478678 | AB11: 0.26572654 | AC11: 1.4189278 | AD11: 0.4014 | AE11: 1.403 | AF11: 2.7017 | AG11: 937.41308 | AH11: 105.9144 | AI11: 99.060442 | AJ11: 106.6131 | AK11: 240.42719 | AL11: 13.9 | AM11: 0.5 | AN11: 11.4 | AO11: 0 | AP11: 5.1 | AQ11: 0.6 | AR11: 1.6 | AS11: 14.3415 | AT11: 33.5415 | AU11: 70.700758 | AV11: 0 | AW11: None Recorded | AX11: None Recorded | AY11: None Recorded | AZ11: Middle | BA11: None Recorded | BB11: - | BC11: 6 | BD11: 7.4074074 | BE11: =U11/((VLOOKUP(B11,'Cell-Characteristics'!$B$4:$E$34,3,FALSE)*VLOOKUP(B11,'Cell-Characteristics'!$B$4:$E$34,4,FALSE)*3600)/1000) -> 1.4681115 | BF11: =(1000*V11)/AD11 -> 21104.087 | BG11: =(1000*W11)/AE11 -> 3593.4918 | BH11: =(1000*X11)/AF11 -> 18238.644 | BI11: =(1000*U11)/AVERAGE(AD11:AF11) -> 41802.131 | BJ11: =BF11/((VLOOKUP(B11,'Cell-Characteristics'!$B$4:$Q$34,13,FALSE))) -> 558.52337 | BK11: =BG11/((VLOOKUP(B11,'Cell-Characteristics'!$B$4:$Q$34,14,FALSE))) -> 1352.1079 | BL11: =BH11/((VLOOKUP(B11,'Cell-Characteristics'!$B$4:$Q$34,15,FALSE))) -> 6862.5773 | BM11: =BI11/((VLOOKUP(B11,'Cell-Characteristics'!$B$4:$Q$34,16,FALSE))) -> 969.86687 | BN11: =AVERAGE(AD11:AF11) -> 1.5020333
B12: KULR 18650-K330 | C12: DLS19_Dec_Run088 | D12: DLS19_Dec | E12: Heater (ISC) | F12: V10.0 | G12: EYAN_1.1_B | H12: 43813 | I12: 61 | J12: 100 | K12: 4.117 | L12: 47.4116 | M12: 47.8 | N12: 48.29 | O12: 18650-Aluminum | P12: 18650-Brass | Q12: Top and Bottom Vent | R12: 53.807256 | S12: 0.0518 | T12: 57.204393 | U12: 58.841852 | V12: 13.715244 | W12: 13.959848 | X12: 31.16676 | Y12: 23.308654 | Z12: 23.724352 | AA12: 52.966993 | AB12: 0.43061597 | AC12: 1.2068429 | AD12: 1.701 | AE12: 1.8001 | AF12: 2.5004 | AG12: 948.68825 | AH12: 100.2492 | AI12: 94.932749 | AJ12: 102.7518 | AK12: 245.00903 | AL12: 21 | AM12: 0 | AN12: 2.9 | AO12: 0.6 | AP12: 1.5 | AQ12: 6.4 | AR12: 0 | AS12: 15.0116 | AT12: 26.4116 | AU12: 55.707042 | AV12: 0 | AW12: None Recorded | AX12: None Recorded | AY12: None Recorded | AZ12: Top | BA12: None Recorded | BB12: - | BC12: 2 | BD12: 2.4691358 | BE12: =U12/((VLOOKUP(B12,'Cell-Characteristics'!$B$4:$E$34,3,FALSE)*VLOOKUP(B12,'Cell-Characteristics'!$B$4:$E$34,4,FALSE)*3600)/1000) -> 1.3758383 | BF12: =(1000*V12)/AD12 -> 8063.0476 | BG12: =(1000*W12)/AE12 -> 7755.0404 | BH12: =(1000*X12)/AF12 -> 12464.71 | BI12: =(1000*U12)/AVERAGE(AD12:AF12) -> 29413.573 | BJ12: =BF12/((VLOOKUP(B12,'Cell-Characteristics'!$B$4:$Q$34,13,FALSE))) -> 213.38997 | BK12: =BG12/((VLOOKUP(B12,'Cell-Characteristics'!$B$4:$Q$34,14,FALSE))) -> 2917.9562 | BL12: =BH12/((VLOOKUP(B12,'Cell-Characteristics'!$B$4:$Q$34,15,FALSE))) -> 4690.0434 | BM12: =BI12/((VLOOKUP(B12,'Cell-Characteristics'!$B$4:$Q$34,16,FALSE))) -> 682.4353 | BN12: =AVERAGE(AD12:AF12) -> 2.0005
B13: KULR 18650-K330 | C13: ESRF18_Oct_Run001 | D13: ESRF18_Oct | E13: Heater (Non-ISC) | F13: V9.0 | G13: EYA_9_H-F | H13: 43399 | I13: 1 | J13: 100 | K13: 4.141 | L13: 47.4114 | M13: 47.3 | N13: 51.1 | O13: 18650-Brass | P13: 18650-Brass | Q13: Top and Bottom Vent | R13: 56.271121 | S13: 0.031 | T13: 58.218167 | U13: 59.716875 | V13: 18.249381 | W13: 14.849271 | X13: 26.618223 | Y13: 30.55984 | Z13: 24.866122 | AA13: 44.574038 | AB13: 0.65570836 | AC13: 0.84299977 | AD13: 6.7259 | AE13: 1.7078 | AF13: 6.7259 | AG13: 965.35832 | AH13: 61.316 | AI13: 59.447109 | AK13: 296.68422 | AL13: 24.0452 | AM13: 0.5 | AN13: 2.35 | AO13: 0.32 | AP13: 1.2 | AQ13: 5.07 | AR13: 0.97 | AS13: 12.9562 | AT13: =L13-AL13 -> 23.3662 | AU13: =100*(AT13/L13) -> 49.283927 | AV13: 0 | AW13: Started data recording about 10 sec after heater start. Top and bottom vent. | AX13: - | AY13: - | AZ13: Middle | BA13: Available | BB13: Both Cell Body TCs failed, set Cell Body equal to average of Cell Chamber TCs, highlighted in yellow. | BC13: 5 | BD13: 10 | BE13: =U13/((VLOOKUP(B13,'Cell-Characteristics'!$B$4:$E$34,3,FALSE)*VLOOKUP(B13,'Cell-Characteristics'!$B$4:$E$34,4,FALSE)*3600)/1000) -> 1.3962981 | BF13: =(1000*V13)/AD13 -> 2713.2995 | BG13: =(1000*W13)/AE13 -> 8694.9709 | BH13: =(1000*X13)/AF13 -> 3957.5704 | BI13: =(1000*U13)/AVERAGE(AD13:AF13) -> 11817.635 | BJ13: =BF13/((VLOOKUP(B13,'Cell-Characteristics'!$B$4:$Q$34,13,FALSE))) -> 71.807949 | BK13: =BG13/((VLOOKUP(B13,'Cell-Characteristics'!$B$4:$Q$34,14,FALSE))) -> 3271.6198 | BL13: =BH13/((VLOOKUP(B13,'Cell-Characteristics'!$B$4:$Q$34,15,FALSE))) -> 1489.0982 | BM13: =BI13/((VLOOKUP(B13,'Cell-Characteristics'!$B$4:$Q$34,16,FALSE))) -> 274.18538 | BN13: =AVERAGE(AD13:AF13) -> 5.0532
B14: KULR 18650-K330 | C14: ESRF18_Oct_Run002 | D14: ESRF18_Oct | E14: Heater (Non-ISC) | F14: V9.0 | G14: EYA_9_H-F | H14: 43399 | I14: 2 | J14: 100 | K14: 4.141 | L14: 47.5045 | M14: 50.5 | N14: 48.5 | O14: 18650-Brass | P14: 18650-Brass | Q14: Top and Bottom Vent | R14: 59.459563 | S14: 0.03 | T14: 61.178666 | U14: 62.379123 | V14: 21.662449 | W14: 8.250473 | X14: 32.466201 | Y14: 34.727082 | Z14: 13.226337 | AA14: 52.046581 | AB14: 0.30072134 | AC14: 0.89973582 | AD14: 5.3216 | AE14: 2.3083 | AF14: 2.71 | AG14: 969.9328 | AH14: 85.1825 | AI14: 82.680905 | AK14: 247.77281 | AL14: 24.0963 | AM14: 0.34 | AN14: 1.04 | AO14: 0.3127 | AP14: 3.253 | AQ14: 5.83 | AR14: 0.822 | AS14: 11.8105 | AT14: =L14-AL14 -> 23.4082 | AU14: =100*(AT14/L14) -> 49.275753 | AV14: 0 | AW14: Header vent; bottom vent; bottom edge breach. | AX14: - | AY14: - | AZ14: Middle | BA14: Available | BB14: TC50 & TC49 manually set equal to TC48. | BC14: 7 | BD14: 14 | BE14: =U14/((VLOOKUP(B14,'Cell-Characteristics'!$B$4:$E$34,3,FALSE)*VLOOKUP(B14,'Cell-Characteristics'!$B$4:$E$34,4,FALSE)*3600)/1000) -> 1.4585466 | BF14: =(1000*V14)/AD14 -> 4070.6647 | BG14: =(1000*W14)/AE14 -> 3574.2637 | BH14: =(1000*X14)/AF14 -> 11980.148 | BI14: =(1000*U14)/AVERAGE(AD14:AF14) -> 18098.567 | BJ14: =BF14/((VLOOKUP(B14,'Cell-Characteristics'!$B$4:$Q$34,13,FALSE))) -> 107.73086 | BK14: =BG14/((VLOOKUP(B14,'Cell-Characteristics'!$B$4:$Q$34,14,FALSE))) -> 1344.8731 | BL14: =BH14/((VLOOKUP(B14,'Cell-Characteristics'!$B$4:$Q$34,15,FALSE))) -> 4507.7194 | BM14: =BI14/((VLOOKUP(B14,'Cell-Characteristics'!$B$4:$Q$34,16,FALSE))) -> 419.91161 | BN14: =AVERAGE(AD14:AF14) -> 3.4466333
B15: KULR 18650-K330 | C15: ESRF18_Oct_Run003 | D15: ESRF18_Oct | E15: Heater (Non-ISC) | F15: V9.0 | G15: EYA_9_H-F | H15: 43399 | I15: 4 | J15: 100 | K15: 4.141 | L15: 47.2836 | M15: 46.6 | N15: 47.9 | O15: 18650-Aluminum | P15: 18650-Brass | Q15: Top and Bottom Vent | R15: 62.054368 | S15: 0.032 | T15: 63.288472 | U15: 65.65392 | V15: 14.28285 | W15: 3.0190027 | X15: 48.352067 | Y15: 21.754756 | Z15: 4.5983585 | AA15: 73.646885 | AB15: 0.32984038 | AC15: 2.0356083 | AD15: 8.5418 | AE15: 1.906 | AF15: 1.6052 | AG15: 977.87385 | AH15: 87.0302 | AI15: 85.129406 | AK15: 252.18554 | AL15: 21.6271 | AM15: 0.3698 | AN15: 0.4313 | AO15: 0.2054 | AP15: 1.6174 | AQ15: 8.4075 | AR15: 0.5721 | AS15: 14.053 | AT15: =L15-AL15 -> 25.6565 | AU15: =100*(AT15/L15) -> 54.260885 | AV15: 0 | AW15: Bottom vent appears to have activated. TC4 is reading a low value relative to the rest. Header and bottom vent; some bottom jellyroll expulsion. | AX15: - | AY15: - | AZ15: Top | BA15: Available | BB15: TC50 & TC49 manually set equal to TC48. | BC15: 6 | BD15: 12 | BE15: =U15/((VLOOKUP(B15,'Cell-Characteristics'!$B$4:$E$34,3,FALSE)*VLOOKUP(B15,'Cell-Characteristics'!$B$4:$E$34,4,FALSE)*3600)/1000) -> 1.5351179 | BF15: =(1000*V15)/AD15 -> 1672.1125 | BG15: =(1000*W15)/AE15 -> 1583.9468 | BH15: =(1000*X15)/AF15 -> 30122.145 | BI15: =(1000*U15)/AVERAGE(AD15:AF15) -> 16341.306 | BJ15: =BF15/((VLOOKUP(B15,'Cell-Characteristics'!$B$4:$Q$34,13,FALSE))) -> 44.25275 | BK15: =BG15/((VLOOKUP(B15,'Cell-Characteristics'!$B$4:$Q$34,14,FALSE))) -> 595.98495 | BL15: =BH15/((VLOOKUP(B15,'Cell-Characteristics'!$B$4:$Q$34,15,FALSE))) -> 11333.932 | BM15: =BI15/((VLOOKUP(B15,'Cell-Characteristics'!$B$4:$Q$34,16,FALSE))) -> 379.14075 | BN15: =AVERAGE(AD15:AF15) -> 4.0176667
B16: KULR 18650-K330 | C16: ESRF18_Oct_Run004 | D16: ESRF18_Oct | E16: Heater (Non-ISC) | F16: V9.0 | G16: EYA_9_H-F | H16: 43399 | I16: 5 | J16: 100 | K16: 4.14 | L16: 47.3373 | M16: 48 | N16: 45.8 | O16: 18650-Aluminum | P16: 18650-Brass | Q16: Top and Bottom Vent | R16: 51.355224 | S16: 0.032 | T16: 55.022728 | U16: 56.054196 | V16: 20.001444 | W16: 23.285013 | X16: 12.76774 | Y16: 35.682331 | Z16: 41.540178 | AA16: 22.777491 | AB16: 0.57954999 | AC16: 0.45191752 | AD16: 5.9305 | AE16: 3.216 | AF16: 5.9305 | AG16: 971.2212 | AH16: 91.3962 | AI16: 88.788092 | AK16: 245.20037 | AL16: 23.1129 | AM16: 5.6031 | AN16: 2.8547 | AO16: 0.5923 | AP16: 0.403 | AQ16: 3.0516 | AR16: 0.1854 | AS16: 11.5343 | AT16: =L16-AL16 -> 24.2244 | AU16: =100*(AT16/L16) -> 51.174021 | AV16: 0 | AW16: Vent prior to failure (catastrophic failure caught in video). header breach; bottom vent; partial jelly roll expulsion. | AX16: - | AY16: - | AZ16: Top | BA16: Available | BB16: TC50 & TC49 manually set equal to TC48. | BC16: 8 | BD16: 16 | BE16: =U16/((VLOOKUP(B16,'Cell-Characteristics'!$B$4:$E$34,3,FALSE)*VLOOKUP(B16,'Cell-Characteristics'!$B$4:$E$34,4,FALSE)*3600)/1000) -> 1.3106574 | BF16: =(1000*V16)/AD16 -> 3372.6404 | BG16: =(1000*W16)/AE16 -> 7240.3647 | BH16: =(1000*X16)/AF16 -> 2152.8943 | BI16: =(1000*U16)/AVERAGE(AD16:AF16) -> 11153.584 | BJ16: =BF16/((VLOOKUP(B16,'Cell-Characteristics'!$B$4:$Q$34,13,FALSE))) -> 89.25752 | BK16: =BG16/((VLOOKUP(B16,'Cell-Characteristics'!$B$4:$Q$34,14,FALSE))) -> 2724.3013 | BL16: =BH16/((VLOOKUP(B16,'Cell-Characteristics'!$B$4:$Q$34,15,FALSE))) -> 810.0604 | BM16: =BI16/((VLOOKUP(B16,'Cell-Characteristics'!$B$4:$Q$34,16,FALSE))) -> 258.77847 | BN16: =AVERAGE(AD16:AF16) -> 5.0256667
B17: KULR 18650-K330 | C17: ESRF18_Oct_Run055 | D17: ESRF18_Oct | E17: Heater (Non-ISC) | F17: V9.0 | G17: EYA_9_H-F | H17: 43402 | I17: 6 | J17: 100 | K17: 4.138 | L17: 47.4078 | M17: 47.7 | N17: 47.9 | O17: 18650-Brass | P17: 18650-Brass | Q17: Top and Bottom Vent | R17: 56.529139 | S17: 0.031 | T17: 61.510806 | U17: 63.066317 | V17: 21.152166 | W17: 21.594016 | X17: 20.320135 | Y17: 33.539561 | Z17: 34.240173 | AA17: 32.220266 | AB17: 1.0011114 | AC17: 0.55439943 | AD17: 3.7136 | AE17: 3.7136 | AF17: 2.8091 | AG17: 24.449983 | AH17: 94.0285 | AI17: 0.009363745 | AK17: 226.20204 | AL17: 20.34 | AM17: 0.9 | AN17: 3.49 | AO17: 0.27 | AP17: 1.77 | AQ17: 6.31 | AR17: 0.36 | AS17: 13.9678 | AT17: =L17-AL17 -> 27.0678 | AU17: =100*(AT17/L17) -> 57.095668 | AV17: 0 | AW17: The nail did not initially penetrate the cell. Multiple attempts were made. The nail became blunt and got stuck in contact with the cell. The heaters were then used to initiate thermal runaway. The calorimetry file is VERY long! Nail pen holes; bottom and top breach; cell severely damaged; can not tell cause of everything though. | AX17: - | AY17: - | AZ17: Middle | BA17: Available | BB17: TC26,TC27 set to 25, TC29, TC30 manually set eual to TC28, TC38 set to TC37 & TC39 manually set equal to TC40,TC45 set to TC44 & TC46 manually set equal to TC47, min & max values on plot axes altered to better display thermal runaway | BC17: 11 | BD17: 22 | BE17: =U17/((VLOOKUP(B17,'Cell-Characteristics'!$B$4:$E$34,3,FALSE)*VLOOKUP(B17,'Cell-Characteristics'!$B$4:$E$34,4,FALSE)*3600)/1000) -> 1.4746146 | BF17: =(1000*V17)/AD17 -> 5695.8655 | BG17: =(1000*W17)/AE17 -> 5814.8471 | BH17: =(1000*X17)/AF17 -> 7233.6816 | BI17: =(1000*U17)/AVERAGE(AD17:AF17) -> 18483.139 | BJ17: =BF17/((VLOOKUP(B17,'Cell-Characteristics'!$B$4:$Q$34,13,FALSE))) -> 150.74208 | BK17: =BG17/((VLOOKUP(B17,'Cell-Characteristics'!$B$4:$Q$34,14,FALSE))) -> 2187.9278 | BL17: =BH17/((VLOOKUP(B17,'Cell-Characteristics'!$B$4:$Q$34,15,FALSE))) -> 2721.7867 | BM17: =BI17/((VLOOKUP(B17,'Cell-Characteristics'!$B$4:$Q$34,16,FALSE))) -> 428.83421 | BN17: =AVERAGE(AD17:AF17) -> 3.4121
B18: KULR 18650-K330 | C18: DLS19_Feb_Run098 | D18: DLS19_Feb | E18: Heater (Non-ISC) | F18: V9.1 | G18: EYA_9.1_H-F | H18: 43512 | I18: 22 | J18: 100 | K18: 4.136 | L18: 45.951 | M18: 48.5 | N18: 49.6 | O18: 18650-Brass | P18: 18650-Brass | Q18: Top and Bottom Vent | R18: 52.275212 | S18: 0.039 | T18: 53.82529 | U18: 54.710731 | V18: 14.884185 | W18: 7.8394522 | X18: 31.987094 | Y18: 27.205238 | Z18: 14.328912 | AA18: 58.46585 | AB18: 0.24431569 | AC18: 0.64112538 | AD18: 1.1062 | AE18: 2.3087 | AF18: 2.2139 | AG18: 963.16463 | AH18: 109.0104 | AI18: 105.1285 | AK18: 225.77041 | AL18: 22.7 | AM18: 1.4 | AN18: 5 | AO18: 0.9 | AP18: 4.44 | AQ18: 1.2 | AR18: 1.64 | AS18: 8.671 | AT18: =L18-AL18 -> 23.251 | AU18: =100*(AT18/L18) -> 50.599552 | AV18: 0 | AW18: All TCs nominal. Standard TR occured. | AX18: 1700 fps, 0.00058 s exposure, 17.9 um pixels. 20 mm x 12 mm FOV. | AY18: miro_projections_84219.hdf | AZ18: Middle | BA18: Available | BB18: TC1 & TC2 changed to X2 and X3, respectvely. Exact test date not recorded in test matrix. Heater current manually changed to 4.0 Amps while in use (RDE tab). TC 49 & TC50 manually set equal to TC48. Positive and negative meshes recorded backwards in matrix. Corrected in EYA. | BC18: 4 | BD18: 8 | BE18: =U18/((VLOOKUP(B18,'Cell-Characteristics'!$B$4:$E$34,3,FALSE)*VLOOKUP(B18,'Cell-Characteristics'!$B$4:$E$34,4,FALSE)*3600)/1000) -> 1.2792445 | BF18: =(1000*V18)/AD18 -> 13455.238 | BG18: =(1000*W18)/AE18 -> 3395.6132 | BH18: =(1000*X18)/AF18 -> 14448.301 | BI18: =(1000*U18)/AVERAGE(AD18:AF18) -> 29159.358 | BJ18: =BF18/((VLOOKUP(B18,'Cell-Characteristics'!$B$4:$Q$34,13,FALSE))) -> 356.09525 | BK18: =BG18/((VLOOKUP(B18,'Cell-Characteristics'!$B$4:$Q$34,14,FALSE))) -> 1277.653 | BL18: =BH18/((VLOOKUP(B18,'Cell-Characteristics'!$B$4:$Q$34,15,FALSE))) -> 5436.401 | BM18: =BI18/((VLOOKUP(B18,'Cell-Characteristics'!$B$4:$Q$34,16,FALSE))) -> 676.53716 | BN18: =AVERAGE(AD18:AF18) -> 1.8762667
B19: KULR 18650-K330 | C19: DLS19_Dec_Run031 | D19: DLS19_Dec | E19: Heater (Non-ISC) | F19: V10.0 | G19: EYAN_1.1_B | H19: 43811 | I19: KULR LR1865HB IV088 00000008 | J19: 100 | K19: 4.131 | L19: 45.9 | M19: 48 | N19: 46.4 | O19: 18650-Aluminum | P19: 18650-Brass | Q19: Top and Bottom Vent | R19: 59.47806 | S19: 0.0442 | T19: 61.670787 | U19: 64.249734 | V19: 13.886485 | W19: 9.0512784 | X19: 41.311971 | Y19: 21.613296 | Z19: 14.087651 | AA19: 64.299053 | AB19: 0.51600887 | AC19: 2.0629382 | AD19: 2.8118 | AE19: 0.9052 | AF19: 2.1103 | AG19: 947.32529 | AH19: 102.051 | AI19: 96.458629 | AJ19: 111.9611 | AK19: 235.51109 | AL19: 14.3 | AM19: 1.9 | AN19: 3.3 | AO19: 0.9 | AP19: 2.9 | AQ19: 5.8 | AR19: 0.6 | AS19: 16.2 | AT19: 31.6 | AU19: 68.845316 | AV19: 0 | AW19: TC 51, 99, 102 are out. Cell vented on top around 230C, failure ensued shortly thereafter. | AX19: 95827(darks), 95828(scan), 95829(flats) | AY19: None Recorded | AZ19: Top | BA19: Available | BB19: - | BC19: 4 | BD19: 4.9382716 | BE19: =U19/((VLOOKUP(B19,'Cell-Characteristics'!$B$4:$E$34,3,FALSE)*VLOOKUP(B19,'Cell-Characteristics'!$B$4:$E$34,4,FALSE)*3600)/1000) -> 1.5022852 | BF19: =(1000*V19)/AD19 -> 4938.646 | BG19: =(1000*W19)/AE19 -> 9999.2028 | BH19: =(1000*X19)/AF19 -> 19576.35 | BI19: =(1000*U19)/AVERAGE(AD19:AF19) -> 33076.931 | BJ19: =BF19/((VLOOKUP(B19,'Cell-Characteristics'!$B$4:$Q$34,13,FALSE))) -> 130.70213 | BK19: =BG19/((VLOOKUP(B19,'Cell-Characteristics'!$B$4:$Q$34,14,FALSE))) -> 3762.3576 | BL19: =BH19/((VLOOKUP(B19,'Cell-Characteristics'!$B$4:$Q$34,15,FALSE))) -> 7365.91 | BM19: =BI19/((VLOOKUP(B19,'Cell-Characteristics'!$B$4:$Q$34,16,FALSE))) -> 767.43025 | BN19: =AVERAGE(AD19:AF19) -> 1.9424333
B20: KULR 18650-K330 | C20: DLS19_Dec_Run032 | D20: DLS19_Dec | E20: Heater (Non-ISC) | F20: V10.0 | G20: EYAN_1.1_B | H20: 43813 | I20: 9 | J20: 100 | K20: 4.131 | L20: 45.9005 | M20: 56.7 | N20: 53.7 | O20: 18650-Aluminum | P20: 18650-Brass | Q20: Top and Bottom Vent | R20: 59.429078 | S20: 0.045 | T20: 61.739207 | U20: 63.399003 | V20: 20.927363 | W20: 9.8109511 | X20: 32.660689 | Y20: 33.008978 | Z20: 15.474929 | AA20: 51.516092 | AB20: 0.37991053 | AC20: 1.2798862 | AD20: 1.4045 | AE20: 1.8069 | AF20: 3.4127 | AG20: 939.44857 | AH20: 98.9591 | AI20: 92.693999 | AJ20: 107.5893 | AK20: 234.09241 | AL20: 20.4 | AM20: 0.5 | AN20: 2 | AO20: 0.7 | AP20: 1.9 | AQ20: 6.4 | AR20: 0.6 | AS20: 13.4005 | AT20: 25.5005 | AU20: 55.55604 | AV20: 0 | AW20: TCs 35, 54 reading lower than neighboring TCs. | AX20: 95971 (data), 95972 (dark), 95973 (bright) | AY20: None Recorded | AZ20: Top | BA20: Available | BB20: - | BC20: 5 | BD20: 6.1728395 | BE20: =U20/((VLOOKUP(B20,'Cell-Characteristics'!$B$4:$E$34,3,FALSE)*VLOOKUP(B20,'Cell-Characteristics'!$B$4:$E$34,4,FALSE)*3600)/1000) -> 1.4823935 | BF20: =(1000*V20)/AD20 -> 14900.223 | BG20: =(1000*W20)/AE20 -> 5429.7145 | BH20: =(1000*X20)/AF20 -> 9570.337 | BI20: =(1000*U20)/AVERAGE(AD20:AF20) -> 28712.883 | BJ20: =BF20/((VLOOKUP(B20,'Cell-Characteristics'!$B$4:$Q$34,13,FALSE))) -> 394.33702 | BK20: =BG20/((VLOOKUP(B20,'Cell-Characteristics'!$B$4:$Q$34,14,FALSE))) -> 2043.0156 | BL20: =BH20/((VLOOKUP(B20,'Cell-Characteristics'!$B$4:$Q$34,15,FALSE))) -> 3600.9901 | BM20: =BI20/((VLOOKUP(B20,'Cell-Characteristics'!$B$4:$Q$34,16,FALSE))) -> 666.17834 | BN20: =AVERAGE(AD20:AF20) -> 2.2080333
B21: KULR 18650-K330 | C21: DLS19_Dec_Run033 | D21: DLS19_Dec | E21: Heater (Non-ISC) | F21: V10.0 | G21: EYAN_1.1_B | H21: 43813 | I21: 18 | J21: 100 | K21: 4.121 | L21: 46.2079 | M21: 49.9 | N21: 54.9 | O21: 18650-Brass | P21: 18650-Brass | Q21: Top Vent Only - Bottom Vent Not Actuated | R21: 54.404334 | S21: 0.0428 | T21: 56.732709 | U21: 58.920667 | V21: 20.879315 | W21: 37.319441 | X21: 0.72191121 | Y21: 35.436317 | Z21: 63.338457 | AA21: 1.2252258 | AB21: 2.1879579 | AC21: 0 | AD21: 3.0056 | AE21: 1.9061 | AF21: 0 | AG21: 939.80926 | AH21: 101.3031 | AI21: 94.936329 | AJ21: 110.1137 | AK21: 230.27685 | AL21: 20.5 | AM21: 1.4 | AN21: 6.9 | AO21: 1.5 | AP21: 0 | AQ21: 0 | AR21: 0 | AS21: 15.9079 | AT21: 25.7079 | AU21: 55.635292 | AV21: 0 | AW21: TC 93 is open. Venting occured fairly nominally, TR ensued shortly thereafter. no bottom vent actuation | AX21: 95977 (data), 95978 (darks), 95979 (brights) | AY21: None Recorded | AZ21: Middle | BA21: Available | BB21: - | BC21: 7 | BD21: 8.6419753 | BE21: =U21/((VLOOKUP(B21,'Cell-Characteristics'!$B$4:$E$34,3,FALSE)*VLOOKUP(B21,'Cell-Characteristics'!$B$4:$E$34,4,FALSE)*3600)/1000) -> 1.3776811 | BF21: =(1000*V21)/AD21 -> 6946.8042 | BG21: =(1000*W21)/AE21 -> 19578.953 | BH21: =(1000*X21)/AF21 -> #DIV/0! | BI21: =(1000*U21)/AVERAGE(AD21:AF21) -> 35987.948 | BJ21: =BF21/((VLOOKUP(B21,'Cell-Characteristics'!$B$4:$Q$34,13,FALSE))) -> 183.84839 | BK21: =BG21/((VLOOKUP(B21,'Cell-Characteristics'!$B$4:$Q$34,14,FALSE))) -> 7366.8894 | BL21: =BH21/((VLOOKUP(B21,'Cell-Characteristics'!$B$4:$Q$34,15,FALSE))) -> #DIV/0! | BM21: =BI21/((VLOOKUP(B21,'Cell-Characteristics'!$B$4:$Q$34,16,FALSE))) -> 834.96982 | BN21: =AVERAGE(AD21:AF21) -> 1.6372333
B22: KULR 18650-K330 | C22: DLS19_Dec_Run034 | D22: DLS19_Dec | E22: Heater (Non-ISC) | F22: V10.0 | G22: EYAN_1.1_B | H22: 43813 | I22: 1 | J22: 100 | K22: 4.124 | L22: 46.0735 | M22: 50.7 | N22: 54.9 | O22: 18650-Brass | P22: 18650-Brass | Q22: Top and Bottom Vent | R22: 57.136515 | S22: 0.045 | T22: 59.671076 | U22: 61.125788 | V22: 17.468902 | W22: 12.156546 | X22: 31.50034 | Y22: 28.578613 | Z22: 19.887753 | AA22: 51.533634 | AB22: 0.35136372 | AC22: 1.1033478 | AD22: 1.1015 | AE22: 1.4009 | AF22: 2.8025 | AG22: 939.67807 | AH22: 102.1898 | AI22: 95.810497 | AJ22: 111.5005 | AK22: 248.68833 | AL22: 19.8 | AM22: 0.5 | AN22: 4.2 | AO22: 0.8 | AP22: 0 | AQ22: 8.4 | AR22: 0.9 | AS22: 11.4735 | AT22: 26.2735 | AU22: 57.025188 | AV22: 0 | AW22: TCs 54, 59, 60 had low readings prior to start of test. | AX22: 95981 (data), 95982 (dark), 95983 (brights) | AY22: None Recorded | AZ22: Middle | BA22: Available | BB22: - | BC22: 6 | BD22: 7.4074074 | BE22: =U22/((VLOOKUP(B22,'Cell-Characteristics'!$B$4:$E$34,3,FALSE)*VLOOKUP(B22,'Cell-Characteristics'!$B$4:$E$34,4,FALSE)*3600)/1000) -> 1.4292412 | BF22: =(1000*V22)/AD22 -> 15859.194 | BG22: =(1000*W22)/AE22 -> 8677.6685 | BH22: =(1000*X22)/AF22 -> 11240.086 | BI22: =(1000*U22)/AVERAGE(AD22:AF22) -> 34567.544 | BJ22: =BF22/((VLOOKUP(B22,'Cell-Characteristics'!$B$4:$Q$34,13,FALSE))) -> 419.71635 | BK22: =BG22/((VLOOKUP(B22,'Cell-Characteristics'!$B$4:$Q$34,14,FALSE))) -> 3265.1095 | BL22: =BH22/((VLOOKUP(B22,'Cell-Characteristics'!$B$4:$Q$34,15,FALSE))) -> 4229.2593 | BM22: =BI22/((VLOOKUP(B22,'Cell-Characteristics'!$B$4:$Q$34,16,FALSE))) -> 802.0145 | BN22: =AVERAGE(AD22:AF22) -> 1.7683
B23: KULR 18650-K330 | C23: ESRF18_Oct_Run057 | D23: ESRF18_Oct | E23: Nail | F23: V9.0 | G23: EYA_9_H-F | H23: 43402 | I23: 10 | J23: 100 | K23: 4.138 | L23: 47.4721 | M23: 45.5 | N23: 47.4 | O23: 18650-Brass | P23: 18650-Brass | Q23: Top Vent Only - Bottom Vent Not Actuated | R23: 59.359218 | S23: 0.01 | T23: 59.843461 | U23: 62.086863 | V23: 18.207671 | W23: 43.146793 | X23: 0.73239873 | Y23: 29.326126 | Z23: 69.494239 | AA23: 1.1796356 | AB23: 2.2434022 | AC23: 0 | AD23: 2.2085 | AE23: 2.2085 | AF23: 0 | AG23: - | AH23: - | AI23: - | AK23: - | AL23: 21.41 | AM23: 1 | AN23: 7.81 | AO23: 7.2 | AP23: 0.11 | AQ23: 0.24 | AR23: 0 | AS23: 9.7021 | AT23: =L23-AL23 -> 26.0621 | AU23: =100*(AT23/L23) -> 54.899825 | AV23: 0 | AW23: TC 8, 26, 32, 50 out. Flame from Nailpen hole. Partial header breach w/ some jelly roll expelled; 2 nail pen holes; Bottom vent not opened. | AX23: - | AY23: - | AZ23: Middle | BA23: Available | BB23: TC29 & TC30 manually set equal to TC28. Test matrix (pre-import) notes: post-test mesh mass not recorded (-). TCs 5&6 set to 4. | BC23: 9 | BD23: 18 | BE23: =U23/((VLOOKUP(B23,'Cell-Characteristics'!$B$4:$E$34,3,FALSE)*VLOOKUP(B23,'Cell-Characteristics'!$B$4:$E$34,4,FALSE)*3600)/1000) -> 1.451713 | BF23: =(1000*V23)/AD23 -> 8244.361 | BG23: =(1000*W23)/AE23 -> 19536.696 | BH23: =(1000*X23)/AF23 -> #DIV/0! | BI23: =(1000*U23)/AVERAGE(AD23:AF23) -> 42169.026 | BJ23: =BF23/((VLOOKUP(B23,'Cell-Characteristics'!$B$4:$Q$34,13,FALSE))) -> 218.18846 | BK23: =BG23/((VLOOKUP(B23,'Cell-Characteristics'!$B$4:$Q$34,14,FALSE))) -> 7350.9896 | BL23: =BH23/((VLOOKUP(B23,'Cell-Characteristics'!$B$4:$Q$34,15,FALSE))) -> #DIV/0! | BM23: =BI23/((VLOOKUP(B23,'Cell-Characteristics'!$B$4:$Q$34,16,FALSE))) -> 978.37934 | BN23: =AVERAGE(AD23:AF23) -> 1.4723333
B24: KULR 18650-K330 | C24: DLS19_Feb_Run051 | D24: DLS19_Feb | E24: Nail | F24: V9.1 | G24: EYA_9.1_H-F | H24: 43511 | I24: 21 | J24: 100 | K24: 4.136 | L24: 46.0092 | M24: 48.5 | N24: 51.1 | O24: 18650-Brass | P24: 18650-Brass | Q24: Top Vent Only - Bottom Vent Not Actuated | R24: 56.678012 | S24: 0.02 | T24: 58.113945 | U24: 59.847586 | V24: 25.377882 | W24: 34.43073 | X24: 0.038974344 | Y24: 42.404186 | Z24: 57.530691 | AA24: 0.065122666 | AB24: 1.7336417 | AC24: 0 | AD24: 2.1002 | AE24: 2.3038 | AF24: 0 | AG24: - | AH24: - | AI24: - | AK24: - | AL24: 25.4 | AM24: 1.4 | AN24: 3.9 | AO24: 3.8 | AP24: 0.1 | AQ24: 0 | AR24: 0 | AS24: 11.4092 | AT24: =L24-AL24 -> 20.6092 | AU24: =100*(AT24/L24) -> 44.79365 | AV24: 0 | AW24: THis is the one with the weird aux cable w/ extensions. All TCs nominal. | AX24: 1700 fps, 0.00058 s exposure, 17.9 um pixels. 20 mm x 12 mm FOV. | AY24: miro_projections_84185.hdf | AZ24: Middle | BA24: Available | BB24: TC1 & TC2 manually changed to X3. Exact test date not recorded in test matrix. All currents & voltages manually set to 0.0 in RDE tab. | BC24: 5 | BD24: 10 | BE24: =U24/((VLOOKUP(B24,'Cell-Characteristics'!$B$4:$E$34,3,FALSE)*VLOOKUP(B24,'Cell-Characteristics'!$B$4:$E$34,4,FALSE)*3600)/1000) -> 1.3993543 | BF24: =(1000*V24)/AD24 -> 12083.555 | BG24: =(1000*W24)/AE24 -> 14945.191 | BH24: =(1000*X24)/AF24 -> #DIV/0! | BI24: =(1000*U24)/AVERAGE(AD24:AF24) -> 40768.111 | BJ24: =BF24/((VLOOKUP(B24,'Cell-Characteristics'!$B$4:$Q$34,13,FALSE))) -> 319.7934 | BK24: =BG24/((VLOOKUP(B24,'Cell-Characteristics'!$B$4:$Q$34,14,FALSE))) -> 5623.3635 | BL24: =BH24/((VLOOKUP(B24,'Cell-Characteristics'!$B$4:$Q$34,15,FALSE))) -> #DIV/0! | BM24: =BI24/((VLOOKUP(B24,'Cell-Characteristics'!$B$4:$Q$34,16,FALSE))) -> 945.87617 | BN24: =AVERAGE(AD24:AF24) -> 1.468
B25: KULR 18650-K330 | C25: DLS19_Feb_Run053 | D25: DLS19_Feb | E25: Nail | F25: V9.1 | G25: EYA_9.1_H-F | H25: 43511 | I25: 18 | J25: 100 | K25: 4.118 | L25: 47.4033 | M25: 46.3 | N25: 46.9 | O25: 18650-Brass | P25: 18650-Brass | Q25: Top and Bottom Vent | R25: 57.088454 | S25: 0.015 | T25: 58.067119 | U25: 59.216349 | V25: 17.687769 | W25: 5.0358878 | X25: 36.492692 | Y25: 29.869739 | Z25: 8.5042187 | AA25: 61.626042 | AB25: 0.18311707 | AC25: 0.96611269 | AD25: 2.5169 | AE25: 2.3152 | AF25: 2.5169 | AG25: - | AH25: - | AI25: - | AK25: - | AL25: 23.1 | AM25: 0.2 | AN25: 1.4 | AO25: 0 | AP25: 1 | AQ25: 6.2 | AR25: 3.6 | AS25: 11.9033 | AT25: =L25-AL25 -> 24.3033 | AU25: =100*(AT25/L25) -> 51.269215 | AV25: 0 | AW25: TC 22 out. Initial push did not work. 2nd attempt initiated TR. | AX25: 1700 fps, 0.00058 s exposure, 17.9 um pixels. 20 mm x 12 mm FOV. | AY25: miro_projections_84193.hdf | AZ25: Middle | BA25: Available | BB25: TC1 & TC2 changed to X3 and X4, respectvely, but values appear low - therefore set to average of cell chamber. Exact test date not recorded in test matrix. All currents & voltages manually set to 0.0 in RDE tab. TC 49 & TC50 manually set equal to TC48. | BC25: 7 | BD25: 14 | BE25: =U25/((VLOOKUP(B25,'Cell-Characteristics'!$B$4:$E$34,3,FALSE)*VLOOKUP(B25,'Cell-Characteristics'!$B$4:$E$34,4,FALSE)*3600)/1000) -> 1.3845948 | BF25: =(1000*V25)/AD25 -> 7027.6011 | BG25: =(1000*W25)/AE25 -> 2175.1416 | BH25: =(1000*X25)/AF25 -> 14499.063 | BI25: =(1000*U25)/AVERAGE(AD25:AF25) -> 24173.227 | BJ25: =BF25/((VLOOKUP(B25,'Cell-Characteristics'!$B$4:$Q$34,13,FALSE))) -> 185.9867 | BK25: =BG25/((VLOOKUP(B25,'Cell-Characteristics'!$B$4:$Q$34,14,FALSE))) -> 818.4313 | BL25: =BH25/((VLOOKUP(B25,'Cell-Characteristics'!$B$4:$Q$34,15,FALSE))) -> 5455.501 | BM25: =BI25/((VLOOKUP(B25,'Cell-Characteristics'!$B$4:$Q$34,16,FALSE))) -> 560.85208 | BN25: =AVERAGE(AD25:AF25) -> 2.4496667
B26: KULR 21700-K500 | C26: DLS19_Dec_Run010 | D26: DLS19_Dec | E26: Heater (ISC) | F26: V10.0 | G26: EYAN_1.1_B | H26: 43811 | I26: 00__ | J26: 100 | K26: 4.156 | L26: 73 | M26: 50.9 | N26: 50.2 | O26: 21700-Brass | P26: 21700-Brass | Q26: Top and Bottom Vent | R26: 74.94594 | S26: 0.0431 | T26: 78.985852 | U26: 83.232881 | V26: 29.018301 | W26: 26.190184 | X26: 28.024396 | Y26: 34.863988 | Z26: 31.466151 | AA26: 33.669861 | AB26: 1.1575088 | AC26: 3.0895205 | AD26: 4.9179 | AE26: 4.9179 | AF26: 3.01 | AG26: 956.71417 | AH26: 93.0137 | AI26: 88.7775 | AJ26: 94.3149 | AK26: 198.81297 | AL26: 39.5 | AM26: 2.4 | AN26: 4.8 | AO26: 0.1 | AP26: 1.7 | AQ26: 3 | AR26: 0 | AS26: 21.5 | AT26: 33.5 | AU26: 45.890411 | AV26: 0 | AW26: TC57, 93 out! TC 30,32 operating? DPA- Central rod ejected from negative terminus of battery and resided in the mating. The jelly roll was visible at the positive terminus but did not eject the battery. | AX26: 95804 (data), 95803 (darks), 95805(brights) | AY26: None Recorded | AZ26: Middle | BA26: Available | BC26: 4 | BD26: 4.9382716 | BE26: =U26/((VLOOKUP(B26,'Cell-Characteristics'!$B$4:$E$34,3,FALSE)*VLOOKUP(B26,'Cell-Characteristics'!$B$4:$E$34,4,FALSE)*3600)/1000) -> 1.284458 | BF26: =(1000*V26)/AD26 -> 5900.5473 | BG26: =(1000*W26)/AE26 -> 5325.4812 | BH26: =(1000*X26)/AF26 -> 9310.4305 | BI26: =(1000*U26)/AVERAGE(AD26:AF26) -> 19438.154 | BJ26: =BF26/((VLOOKUP(B26,'Cell-Characteristics'!$B$4:$Q$34,13,FALSE))) -> 109.61647 | BK26: =BG26/((VLOOKUP(B26,'Cell-Characteristics'!$B$4:$Q$34,14,FALSE))) -> 1440.6873 | BL26: =BH26/((VLOOKUP(B26,'Cell-Characteristics'!$B$4:$Q$34,15,FALSE))) -> 2518.7243 | BM26: =BI26/((VLOOKUP(B26,'Cell-Characteristics'!$B$4:$Q$34,16,FALSE))) -> 317.5028 | BN26: =AVERAGE(AD26:AF26) -> 4.2819333
B27: KULR 21700-K500 | C27: DLS19_Dec_Run012 | D27: DLS19_Dec | E27: Heater (ISC) | F27: V10.0 | G27: EYAN_1.1_B | H27: 43811 | I27: 36130 | J27: 100 | K27: 4.168 | L27: 72.6 | M27: 49.39 | N27: 51.3 | O27: 21700-Brass | P27: 21700-Brass | Q27: Top and Bottom Vent | R27: 91.329406 | S27: 0.0463 | T27: 94.160639 | U27: 96.213502 | V27: 26.707617 | W27: 26.05693 | X27: 43.448955 | Y27: 27.7587 | Z27: 27.082404 | AA27: 45.158896 | AB27: 0.90824167 | AC27: 1.1446209 | AD27: 6.1133 | AE27: 1.703 | AF27: 2.2048 | AG27: 929.33604 | AH27: 113.0937 | AI27: 104.95235 | AJ27: 114.5967 | AK27: 231.61023 | AL27: 31.2 | AM27: 3.1 | AN27: 3 | AO27: 2.7 | AP27: 7 | AQ27: 5.9 | AR27: 4.3 | AS27: 15.4 | AT27: 41.4 | AU27: 57.024793 | AV27: 0 | AW27: TC 59, 102 | AX27: 95806 (data) | AY27: None Recorded | AZ27: Middle | BA27: Available | BC27: 5 | BD27: 6.1728395 | BE27: =U27/((VLOOKUP(B27,'Cell-Characteristics'!$B$4:$E$34,3,FALSE)*VLOOKUP(B27,'Cell-Characteristics'!$B$4:$E$34,4,FALSE)*3600)/1000) -> 1.4847763 | BF27: =(1000*V27)/AD27 -> 4368.7725 | BG27: =(1000*W27)/AE27 -> 15300.605 | BH27: =(1000*X27)/AF27 -> 19706.529 | BI27: =(1000*U27)/AVERAGE(AD27:AF27) -> 28803.276 | BJ27: =BF27/((VLOOKUP(B27,'Cell-Characteristics'!$B$4:$Q$34,13,FALSE))) -> 81.160171 | BK27: =BG27/((VLOOKUP(B27,'Cell-Characteristics'!$B$4:$Q$34,14,FALSE))) -> 4139.2291 | BL27: =BH27/((VLOOKUP(B27,'Cell-Characteristics'!$B$4:$Q$34,15,FALSE))) -> 5331.1514 | BM27: =BI27/((VLOOKUP(B27,'Cell-Characteristics'!$B$4:$Q$34,16,FALSE))) -> 470.47269 | BN27: =AVERAGE(AD27:AF27) -> 3.3403667
B28: KULR 21700-K500 | C28: DLS19_Dec_Run014 | D28: DLS19_Dec | E28: Heater (ISC) | F28: V10.0 | G28: EYAN_1.1_B | H28: 43811 | I28: K-ISC-LS-8001:0081 | J28: 100 | K28: 4.153 | L28: 73.2 | M28: 47.6 | N28: 47.7 | O28: 21700-Brass | P28: 21700-Brass | Q28: Top and Bottom Vent | R28: 84.683043 | S28: 0.0409 | T28: 87.540661 | U28: 95.070241 | V28: 24.567803 | W28: 41.176587 | X28: 29.325852 | Y28: 25.841738 | Z28: 43.311752 | AA28: 30.84651 | AB28: 2.9338818 | AC28: 4.595699 | AD28: 5.0225 | AE28: 5.0225 | AF28: 3.5159 | AG28: 951.7815 | AH28: 70.9578 | AI28: 67.290654 | AJ28: 73.1585 | AK28: 138.29991 | AL28: 32.9 | AM28: 0.6 | AN28: 5.2 | AO28: 0 | AP28: 4.4 | AQ28: 0.9 | AR28: 0 | AS28: 29.2 | AT28: 40.3 | AU28: 55.054645 | AV28: 0 | AW28: Found in fumehood (0081 and 14 on it in sharpie, connected to Gamry 09080). TC 57, 93 out | AX28: 95808 (data), | AY28: None Recorded | AZ28: Middle | BA28: Available | BC28: 6 | BD28: 7.4074074 | BE28: =U28/((VLOOKUP(B28,'Cell-Characteristics'!$B$4:$E$34,3,FALSE)*VLOOKUP(B28,'Cell-Characteristics'!$B$4:$E$34,4,FALSE)*3600)/1000) -> 1.4671334 | BF28: =(1000*V28)/AD28 -> 4891.5486 | BG28: =(1000*W28)/AE28 -> 8198.4245 | BH28: =(1000*X28)/AF28 -> 8340.9231 | BI28: =(1000*U28)/AVERAGE(AD28:AF28) -> 21031.843 | BJ28: =BF28/((VLOOKUP(B28,'Cell-Characteristics'!$B$4:$Q$34,13,FALSE))) -> 90.87196 | BK28: =BG28/((VLOOKUP(B28,'Cell-Characteristics'!$B$4:$Q$34,14,FALSE))) -> 2217.8965 | BL28: =BH28/((VLOOKUP(B28,'Cell-Characteristics'!$B$4:$Q$34,15,FALSE))) -> 2256.4462 | BM28: =BI28/((VLOOKUP(B28,'Cell-Characteristics'!$B$4:$Q$34,16,FALSE))) -> 343.53412 | BN28: =AVERAGE(AD28:AF28) -> 4.5203
B29: KULR 21700-K500 | C29: DLS19_Dec_Run016 | D29: DLS19_Dec | E29: Heater (ISC) | F29: V10.0 | G29: EYAN_1.1_B | H29: 43811 | I29: K-ISC-LS-8001-0087 | J29: 100 | K29: 4.153 | L29: 72.5 | M29: 51.1 | N29: 52.09 | O29: 21700-Aluminum | P29: 21700-Aluminum | Q29: Top and Bottom Vent | R29: 78.301839 | S29: 0.0396 | T29: 82.836737 | U29: 84.50732 | V29: 21.134289 | W29: 38.498378 | X29: 24.874652 | Y29: 25.008827 | Z29: 45.556265 | AA29: 29.434909 | AB29: 0.99453673 | AC29: 0.67604594 | AD29: =AE29 -> 3.3051 | AE29: 3.3051 | AF29: 3.2045 | AG29: 924.52321 | AH29: 75.3585 | AI29: 69.371998 | AJ29: 79.2654 | AK29: 219.82652 | AL29: 39.3 | AM29: 4.1 | AN29: 4.7 | AO29: 1.5 | AP29: 1.9 | AQ29: 3.7 | AR29: 0.81 | AS29: 16.49 | AT29: 33.2 | AU29: 45.793103 | AW29: Found in fumehood (0087 and 16 on it in sharpie, connected to Gamry 09080). two aluminum seals found during dpa. jelly still in can. | AX29: 95809(scan), 95810(darks), 95811(flats - shutter closed note), 95812(flats - good) | AY29: None Recorded | AZ29: Top | BA29: Available | BC29: 6 | BD29: 7.4074074 | BE29: =U29/((VLOOKUP(B29,'Cell-Characteristics'!$B$4:$E$34,3,FALSE)*VLOOKUP(B29,'Cell-Characteristics'!$B$4:$E$34,4,FALSE)*3600)/1000) -> 1.3041253 | BF29: =(1000*V29)/AD29 -> 6394.4477 | BG29: =(1000*W29)/AE29 -> 11648.174 | BH29: =(1000*X29)/AF29 -> 7762.413 | BI29: =(1000*U29)/AVERAGE(AD29:AF29) -> 25830.841 | BJ29: =BF29/((VLOOKUP(B29,'Cell-Characteristics'!$B$4:$Q$34,13,FALSE))) -> 118.79183 | BK29: =BG29/((VLOOKUP(B29,'Cell-Characteristics'!$B$4:$Q$34,14,FALSE))) -> 3151.1473 | BL29: =BH29/((VLOOKUP(B29,'Cell-Characteristics'!$B$4:$Q$34,15,FALSE))) -> 2099.9436 | BM29: =BI29/((VLOOKUP(B29,'Cell-Characteristics'!$B$4:$Q$34,16,FALSE))) -> 421.92095 | BN29: =AVERAGE(AD29:AF29) -> 3.2715667
